telegram.ext.dispatcher - ERROR - No error handlers are registered, logging exception.
Traceback (most recent call last):
  File "C:\projects\venv\lib\site-packages\telegram\ext\dispatcher.py", line 372, in process_update
    handler.handle_update(update, self, check, context)
  File "C:\projects\venv\lib\site-packages\telegram\ext\handler.py", line 120, in handle_update
    return self.callback(dispatcher.bot, update, **optional_args)
  File "bot.py", line 19, in greet_user
    update.message(text)
TypeError: 'Message' object is not callable
telegram.ext.dispatcher - ERROR - No error handlers are registered, logging exception.
Traceback (most recent call last):
  File "C:\projects\venv\lib\site-packages\telegram\ext\dispatcher.py", line 372, in process_update
    handler.handle_update(update, self, check, context)
  File "C:\projects\venv\lib\site-packages\telegram\ext\handler.py", line 120, in handle_update
    return self.callback(dispatcher.bot, update, **optional_args)
  File "bot.py", line 19, in greet_user
    update.message(text)
TypeError: 'Message' object is not callable
telegram.ext.updater - INFO - Received signal 2 (SIGINT), stopping...
telegram.ext.updater - WARNING - Exiting immediately!
telegram.ext.updater - INFO - Received signal 2 (SIGINT), stopping...
telegram.ext.updater - WARNING - Exiting immediately!
telegram.ext.updater - INFO - Received signal 2 (SIGINT), stopping...
telegram.ext.updater - WARNING - Exiting immediately!
telegram.ext.updater - INFO - Received signal 2 (SIGINT), stopping...
telegram.ext.updater - INFO - Received signal 2 (SIGINT), stopping...
telegram.ext.updater - WARNING - Exiting immediately!
telegram.ext.updater - INFO - Received signal 2 (SIGINT), stopping...
telegram.vendor.ptb_urllib3.urllib3.connectionpool - WARNING - Retrying (Retry(total=2, connect=None, read=None, redirect=None)) after connection broken by 'ConnectTimeoutError(<telegram.vendor.ptb_urllib3.urllib3.connection.VerifiedHTTPSConnection object at 0x000001A7DA3E9A58>, 'Connection to api.telegram.org timed out. (connect timeout=5.0)')': /bot981618516:AAHrGxYlAegMtnXlB4Ywf5N3dHJv5gAMBvQ/getMe
telegram.vendor.ptb_urllib3.urllib3.connectionpool - WARNING - Retrying (Retry(total=1, connect=None, read=None, redirect=None)) after connection broken by 'ConnectTimeoutError(<telegram.vendor.ptb_urllib3.urllib3.connection.VerifiedHTTPSConnection object at 0x000001A7DA3E9B70>, 'Connection to api.telegram.org timed out. (connect timeout=5.0)')': /bot981618516:AAHrGxYlAegMtnXlB4Ywf5N3dHJv5gAMBvQ/getMe
telegram.vendor.ptb_urllib3.urllib3.connectionpool - WARNING - Retrying (Retry(total=0, connect=None, read=None, redirect=None)) after connection broken by 'ConnectTimeoutError(<telegram.vendor.ptb_urllib3.urllib3.connection.VerifiedHTTPSConnection object at 0x000001A7DA3E9C18>, 'Connection to api.telegram.org timed out. (connect timeout=5.0)')': /bot981618516:AAHrGxYlAegMtnXlB4Ywf5N3dHJv5gAMBvQ/getMe
telegram.vendor.ptb_urllib3.urllib3.connectionpool - WARNING - Retrying (Retry(total=2, connect=None, read=None, redirect=None)) after connection broken by 'ConnectTimeoutError(<telegram.vendor.ptb_urllib3.urllib3.connection.VerifiedHTTPSConnection object at 0x000001FFAC199A58>, 'Connection to api.telegram.org timed out. (connect timeout=5.0)')': /bot981618516:AAHrGxYlAegMtnXlB4Ywf5N3dHJv5gAMBvQ/getMe
telegram.vendor.ptb_urllib3.urllib3.connectionpool - WARNING - Retrying (Retry(total=1, connect=None, read=None, redirect=None)) after connection broken by 'ConnectTimeoutError(<telegram.vendor.ptb_urllib3.urllib3.connection.VerifiedHTTPSConnection object at 0x000001FFAC199B70>, 'Connection to api.telegram.org timed out. (connect timeout=5.0)')': /bot981618516:AAHrGxYlAegMtnXlB4Ywf5N3dHJv5gAMBvQ/getMe
telegram.vendor.ptb_urllib3.urllib3.connectionpool - WARNING - Retrying (Retry(total=0, connect=None, read=None, redirect=None)) after connection broken by 'ConnectTimeoutError(<telegram.vendor.ptb_urllib3.urllib3.connection.VerifiedHTTPSConnection object at 0x000001FFAC199C18>, 'Connection to api.telegram.org timed out. (connect timeout=5.0)')': /bot981618516:AAHrGxYlAegMtnXlB4Ywf5N3dHJv5gAMBvQ/getMe
telegram.vendor.ptb_urllib3.urllib3.connectionpool - WARNING - Retrying (Retry(total=2, connect=None, read=None, redirect=None)) after connection broken by 'ConnectTimeoutError(<telegram.vendor.ptb_urllib3.urllib3.connection.VerifiedHTTPSConnection object at 0x00000242EE649A58>, 'Connection to api.telegram.org timed out. (connect timeout=5.0)')': /bot981618516:AAHrGxYlAegMtnXlB4Ywf5N3dHJv5gAMBvQ/getMe
telegram.vendor.ptb_urllib3.urllib3.connectionpool - WARNING - Retrying (Retry(total=1, connect=None, read=None, redirect=None)) after connection broken by 'ConnectTimeoutError(<telegram.vendor.ptb_urllib3.urllib3.connection.VerifiedHTTPSConnection object at 0x00000242EE649B70>, 'Connection to api.telegram.org timed out. (connect timeout=5.0)')': /bot981618516:AAHrGxYlAegMtnXlB4Ywf5N3dHJv5gAMBvQ/getMe
telegram.vendor.ptb_urllib3.urllib3.connectionpool - WARNING - Retrying (Retry(total=0, connect=None, read=None, redirect=None)) after connection broken by 'ConnectTimeoutError(<telegram.vendor.ptb_urllib3.urllib3.connection.VerifiedHTTPSConnection object at 0x00000242EE649C18>, 'Connection to api.telegram.org timed out. (connect timeout=5.0)')': /bot981618516:AAHrGxYlAegMtnXlB4Ywf5N3dHJv5gAMBvQ/getMe
telegram.ext.dispatcher - ERROR - No error handlers are registered, logging exception.
Traceback (most recent call last):
  File "C:\projects\venv\lib\site-packages\telegram\ext\dispatcher.py", line 372, in process_update
    handler.handle_update(update, self, check, context)
  File "C:\projects\venv\lib\site-packages\telegram\ext\handler.py", line 120, in handle_update
    return self.callback(dispatcher.bot, update, **optional_args)
TypeError: talk_to_me() takes 1 positional argument but 2 were given
telegram.ext.dispatcher - ERROR - No error handlers are registered, logging exception.
Traceback (most recent call last):
  File "C:\projects\venv\lib\site-packages\telegram\ext\dispatcher.py", line 372, in process_update
    handler.handle_update(update, self, check, context)
  File "C:\projects\venv\lib\site-packages\telegram\ext\handler.py", line 120, in handle_update
    return self.callback(dispatcher.bot, update, **optional_args)
TypeError: greet_user() takes 1 positional argument but 2 were given
telegram.ext.dispatcher - ERROR - No error handlers are registered, logging exception.
Traceback (most recent call last):
  File "C:\projects\venv\lib\site-packages\telegram\ext\dispatcher.py", line 372, in process_update
    handler.handle_update(update, self, check, context)
  File "C:\projects\venv\lib\site-packages\telegram\ext\handler.py", line 120, in handle_update
    return self.callback(dispatcher.bot, update, **optional_args)
TypeError: greet_user() takes 1 positional argument but 2 were given
telegram.ext.dispatcher - ERROR - No error handlers are registered, logging exception.
Traceback (most recent call last):
  File "C:\projects\venv\lib\site-packages\telegram\ext\dispatcher.py", line 372, in process_update
    handler.handle_update(update, self, check, context)
  File "C:\projects\venv\lib\site-packages\telegram\ext\handler.py", line 120, in handle_update
    return self.callback(dispatcher.bot, update, **optional_args)
TypeError: greet_user() takes 1 positional argument but 2 were given
telegram.ext.updater - INFO - Received signal 2 (SIGINT), stopping...
telegram.ext.dispatcher - ERROR - No error handlers are registered, logging exception.
Traceback (most recent call last):
  File "C:\projects\venv\lib\site-packages\telegram\ext\dispatcher.py", line 372, in process_update
    handler.handle_update(update, self, check, context)
  File "C:\projects\venv\lib\site-packages\telegram\ext\handler.py", line 120, in handle_update
    return self.callback(dispatcher.bot, update, **optional_args)
TypeError: talk_to_me() takes 1 positional argument but 2 were given
telegram.ext.dispatcher - ERROR - No error handlers are registered, logging exception.
Traceback (most recent call last):
  File "C:\projects\venv\lib\site-packages\telegram\ext\dispatcher.py", line 372, in process_update
    handler.handle_update(update, self, check, context)
  File "C:\projects\venv\lib\site-packages\telegram\ext\handler.py", line 120, in handle_update
    return self.callback(dispatcher.bot, update, **optional_args)
TypeError: talk_to_me() takes 1 positional argument but 2 were given
telegram.ext.updater - INFO - Received signal 2 (SIGINT), stopping...
telegram.ext.updater - WARNING - Exiting immediately!
telegram.vendor.ptb_urllib3.urllib3.connectionpool - WARNING - Retrying (Retry(total=2, connect=None, read=None, redirect=None)) after connection broken by 'ProxyError('Cannot connect to proxy.', timeout('timed out',))': /bot981618516:AAHrGxYlAegMtnXlB4Ywf5N3dHJv5gAMBvQ/getMe
telegram.vendor.ptb_urllib3.urllib3.connectionpool - WARNING - Retrying (Retry(total=1, connect=None, read=None, redirect=None)) after connection broken by 'ProxyError('Cannot connect to proxy.', timeout('timed out',))': /bot981618516:AAHrGxYlAegMtnXlB4Ywf5N3dHJv5gAMBvQ/getMe
telegram.vendor.ptb_urllib3.urllib3.connectionpool - WARNING - Retrying (Retry(total=0, connect=None, read=None, redirect=None)) after connection broken by 'ProxyError('Cannot connect to proxy.', timeout('timed out',))': /bot981618516:AAHrGxYlAegMtnXlB4Ywf5N3dHJv5gAMBvQ/getMe
telegram.ext.updater - INFO - Received signal 2 (SIGINT), stopping...
telegram.ext.updater - WARNING - Exiting immediately!
telegram.ext.dispatcher - ERROR - No error handlers are registered, logging exception.
Traceback (most recent call last):
  File "C:\projects\venv\lib\site-packages\telegram\ext\dispatcher.py", line 372, in process_update
    handler.handle_update(update, self, check, context)
  File "C:\projects\venv\lib\site-packages\telegram\ext\handler.py", line 120, in handle_update
    return self.callback(dispatcher.bot, update, **optional_args)
  File "bot.py", line 35, in constellation
    chosen_planet = getattr(ephem, planet_name)
AttributeError: module 'ephem' has no attribute 'Earth'
telegram.ext.dispatcher - ERROR - No error handlers are registered, logging exception.
Traceback (most recent call last):
  File "C:\projects\venv\lib\site-packages\telegram\ext\dispatcher.py", line 372, in process_update
    handler.handle_update(update, self, check, context)
  File "C:\projects\venv\lib\site-packages\telegram\ext\handler.py", line 120, in handle_update
    return self.callback(dispatcher.bot, update, **optional_args)
  File "bot.py", line 35, in constellation
    chosen_planet = getattr(ephem, planet_name)
AttributeError: module 'ephem' has no attribute 'Earth'
telegram.ext.updater - INFO - Received signal 2 (SIGINT), stopping...
telegram.ext.updater - WARNING - Exiting immediately!
telegram.ext.updater - INFO - Received signal 2 (SIGINT), stopping...
telegram.ext.updater - WARNING - Exiting immediately!
telegram.ext.updater - INFO - Received signal 2 (SIGINT), stopping...
telegram.ext.updater - WARNING - Exiting immediately!
telegram.ext.updater - INFO - Received signal 2 (SIGINT), stopping...
telegram.ext.updater - WARNING - Exiting immediately!
telegram.vendor.ptb_urllib3.urllib3.connectionpool - WARNING - Retrying (Retry(total=2, connect=None, read=None, redirect=None)) after connection broken by 'ProxyError('Cannot connect to proxy.', timeout('timed out',))': /bot981618516:AAHrGxYlAegMtnXlB4Ywf5N3dHJv5gAMBvQ/getMe
telegram.ext.updater - INFO - Received signal 2 (SIGINT), stopping...
telegram.ext.updater - WARNING - Exiting immediately!
telegram.vendor.ptb_urllib3.urllib3.connectionpool - WARNING - Retrying (Retry(total=2, connect=None, read=None, redirect=None)) after connection broken by 'ProxyError('Cannot connect to proxy.', timeout('timed out',))': /bot981618516:AAHrGxYlAegMtnXlB4Ywf5N3dHJv5gAMBvQ/getUpdates
telegram.vendor.ptb_urllib3.urllib3.connectionpool - WARNING - Retrying (Retry(total=1, connect=None, read=None, redirect=None)) after connection broken by 'ProxyError('Cannot connect to proxy.', timeout('timed out',))': /bot981618516:AAHrGxYlAegMtnXlB4Ywf5N3dHJv5gAMBvQ/getUpdates
telegram.vendor.ptb_urllib3.urllib3.connectionpool - WARNING - Retrying (Retry(total=0, connect=None, read=None, redirect=None)) after connection broken by 'ProxyError('Cannot connect to proxy.', timeout('timed out',))': /bot981618516:AAHrGxYlAegMtnXlB4Ywf5N3dHJv5gAMBvQ/getUpdates
telegram.ext.updater - INFO - Received signal 2 (SIGINT), stopping...
telegram.ext.updater - WARNING - Exiting immediately!
